Traceback (most recent call last):
  File "c:\users\phil\miniwin\envs\ebp\lib\site-packages\jupyter_cache\executors\basic.py", line 157, in execute
      executenb(nb_bundle.nb, cwd=tmpdirname)
        File "c:\users\phil\miniwin\envs\ebp\lib\site-packages\nbconvert\preprocessors\execute.py", line 737, in executenb
	    return ep.preprocess(nb, resources, km=km)[0]
	      File "c:\users\phil\miniwin\envs\ebp\lib\site-packages\nbconvert\preprocessors\execute.py", line 405, in preprocess
	          nb, resources = super(ExecutePreprocessor, self).preprocess(nb, resources)
		    File "c:\users\phil\miniwin\envs\ebp\lib\site-packages\nbconvert\preprocessors\base.py", line 69, in preprocess
		        nb.cells[index], resources = self.preprocess_cell(cell, resources, index)
			  File "c:\users\phil\miniwin\envs\ebp\lib\site-packages\nbconvert\preprocessors\execute.py", line 448, in preprocess_cell
			      raise CellExecutionError.from_cell_and_msg(cell, out)
			      nbconvert.preprocessors.execute.CellExecutionError: An error occurred while executing the following cell:
			      ------------------
			      indices_data = read_data(
			              indices_list,
				              start=dt.datetime(1928, 1, 2),
					              end=dt.datetime(2020, 12, 31)
						      )
						      ------------------

^[[1;31m---------------------------------------------------------------------------^[[0m
^[[1;31mOverflowError^[[0m                             Traceback (most recent call last)
^[[1;32m<ipython-input-43-e1341c1459ea>^[[0m in ^[[0;36m<module>^[[1;34m^[[0m
^[[0;32m      2^[[0m         ^[[0mindices_list^[[0m^[[1;33m,^[[0m^[[1;33m^[[0m^[[1;33m^[[0m^[[0m
^[[0;32m      3^[[0m         ^[[0mstart^[[0m^[[1;33m=^[[0m^[[0mdt^[[0m^[[1;33m.^[[0m^[[0mdatetime^[[0m^[[
