Traceback (most recent call last):
  File "/Users/junaluzi/opt/anaconda3/envs/quant-econ-book/lib/python3.8/site-packages/jupyter_cache/executors/basic.py", line 157, in execute
    executenb(nb_bundle.nb, cwd=tmpdirname)
  File "/Users/junaluzi/opt/anaconda3/envs/quant-econ-book/lib/python3.8/site-packages/nbconvert/preprocessors/execute.py", line 737, in executenb
    return ep.preprocess(nb, resources, km=km)[0]
  File "/Users/junaluzi/opt/anaconda3/envs/quant-econ-book/lib/python3.8/site-packages/nbconvert/preprocessors/execute.py", line 405, in preprocess
    nb, resources = super(ExecutePreprocessor, self).preprocess(nb, resources)
  File "/Users/junaluzi/opt/anaconda3/envs/quant-econ-book/lib/python3.8/site-packages/nbconvert/preprocessors/base.py", line 69, in preprocess
    nb.cells[index], resources = self.preprocess_cell(cell, resources, index)
  File "/Users/junaluzi/opt/anaconda3/envs/quant-econ-book/lib/python3.8/site-packages/nbconvert/preprocessors/execute.py", line 448, in preprocess_cell
    raise CellExecutionError.from_cell_and_msg(cell, out)
nbconvert.preprocessors.execute.CellExecutionError: An error occurred while executing the following cell:
------------------
from myst_nb import glue
glue("test_program_1_updated", fig, display=False)
------------------

[0;31m---------------------------------------------------------------------------[0m
[0;31mNameError[0m                                 Traceback (most recent call last)
[0;32m<ipython-input-3-643e5444ec0c>[0m in [0;36m<module>[0;34m[0m
[1;32m      1[0m [0;32mfrom[0m [0mmyst_nb[0m [0;32mimport[0m [0mglue[0m[0;34m[0m[0;34m[0m[0m
[0;32m----> 2[0;31m [0mglue[0m[0;34m([0m[0;34m"test_program_1_updated"[0m[0;34m,[0m [0mfig[0m[0;34m,[0m [0mdisplay[0m[0;34m=[0m[0;32mFalse[0m[0;34m)[0m[0;34m[0m[0;34m[0m[0m
[0m
[0;31mNameError[0m: name 'fig' is not defined
NameError: name 'fig' is not defined

